17/02/21 (15:19:59) | ERROR: <urlopen error [Errno 61] Connection refused>
Traceback (most recent call last):
  File "/usr/local/Cellar/python@3.9/3.9.1_8/Frameworks/Python.framework/Versions/3.9/lib/python3.9/urllib/request.py", line 1342, in do_open
    h.request(req.get_method(), req.selector, req.data, headers,
  File "/usr/local/Cellar/python@3.9/3.9.1_8/Frameworks/Python.framework/Versions/3.9/lib/python3.9/http/client.py", line 1255, in request
    self._send_request(method, url, body, headers, encode_chunked)
  File "/usr/local/Cellar/python@3.9/3.9.1_8/Frameworks/Python.framework/Versions/3.9/lib/python3.9/http/client.py", line 1301, in _send_request
    self.endheaders(body, encode_chunked=encode_chunked)
  File "/usr/local/Cellar/python@3.9/3.9.1_8/Frameworks/Python.framework/Versions/3.9/lib/python3.9/http/client.py", line 1250, in endheaders
    self._send_output(message_body, encode_chunked=encode_chunked)
  File "/usr/local/Cellar/python@3.9/3.9.1_8/Frameworks/Python.framework/Versions/3.9/lib/python3.9/http/client.py", line 1010, in _send_output
    self.send(msg)
  File "/usr/local/Cellar/python@3.9/3.9.1_8/Frameworks/Python.framework/Versions/3.9/lib/python3.9/http/client.py", line 950, in send
    self.connect()
  File "/usr/local/Cellar/python@3.9/3.9.1_8/Frameworks/Python.framework/Versions/3.9/lib/python3.9/http/client.py", line 1417, in connect
    super().connect()
  File "/usr/local/Cellar/python@3.9/3.9.1_8/Frameworks/Python.framework/Versions/3.9/lib/python3.9/http/client.py", line 921, in connect
    self.sock = self._create_connection(
  File "/usr/local/Cellar/python@3.9/3.9.1_8/Frameworks/Python.framework/Versions/3.9/lib/python3.9/socket.py", line 843, in create_connection
    raise err
  File "/usr/local/Cellar/python@3.9/3.9.1_8/Frameworks/Python.framework/Versions/3.9/lib/python3.9/socket.py", line 831, in create_connection
    sock.connect(sa)
ConnectionRefusedError: [Errno 61] Connection refused

During handling of the above exception, another exception occurred:

Traceback (most recent call last):
  File "/usr/local/Cellar/bpytop/1.0.62/libexec/lib/python3.9/site-packages/bpytop.py", line 4946, in _checker
    with urllib.request.urlopen("https://github.com/aristocratos/bpytop/raw/master/bpytop.py", timeout=5) as source: # type: ignore
  File "/usr/local/Cellar/python@3.9/3.9.1_8/Frameworks/Python.framework/Versions/3.9/lib/python3.9/urllib/request.py", line 214, in urlopen
    return opener.open(url, data, timeout)
  File "/usr/local/Cellar/python@3.9/3.9.1_8/Frameworks/Python.framework/Versions/3.9/lib/python3.9/urllib/request.py", line 523, in open
    response = meth(req, response)
  File "/usr/local/Cellar/python@3.9/3.9.1_8/Frameworks/Python.framework/Versions/3.9/lib/python3.9/urllib/request.py", line 632, in http_response
    response = self.parent.error(
  File "/usr/local/Cellar/python@3.9/3.9.1_8/Frameworks/Python.framework/Versions/3.9/lib/python3.9/urllib/request.py", line 555, in error
    result = self._call_chain(*args)
  File "/usr/local/Cellar/python@3.9/3.9.1_8/Frameworks/Python.framework/Versions/3.9/lib/python3.9/urllib/request.py", line 494, in _call_chain
    result = func(*args)
  File "/usr/local/Cellar/python@3.9/3.9.1_8/Frameworks/Python.framework/Versions/3.9/lib/python3.9/urllib/request.py", line 747, in http_error_302
    return self.parent.open(new, timeout=req.timeout)
  File "/usr/local/Cellar/python@3.9/3.9.1_8/Frameworks/Python.framework/Versions/3.9/lib/python3.9/urllib/request.py", line 517, in open
    response = self._open(req, data)
  File "/usr/local/Cellar/python@3.9/3.9.1_8/Frameworks/Python.framework/Versions/3.9/lib/python3.9/urllib/request.py", line 534, in _open
    result = self._call_chain(self.handle_open, protocol, protocol +
  File "/usr/local/Cellar/python@3.9/3.9.1_8/Frameworks/Python.framework/Versions/3.9/lib/python3.9/urllib/request.py", line 494, in _call_chain
    result = func(*args)
  File "/usr/local/Cellar/python@3.9/3.9.1_8/Frameworks/Python.framework/Versions/3.9/lib/python3.9/urllib/request.py", line 1385, in https_open
    return self.do_open(http.client.HTTPSConnection, req,
  File "/usr/local/Cellar/python@3.9/3.9.1_8/Frameworks/Python.framework/Versions/3.9/lib/python3.9/urllib/request.py", line 1345, in do_open
    raise URLError(err)
urllib.error.URLError: <urlopen error [Errno 61] Connection refused>
